Workbook

Sheet Summary
A1: ALLFED agricultural input scale-up — code-matched workbook
A3: Each commodity has: CAPEX sheet + Ramp-up sheet (same layout as N template).
A4: Budgets = equal-pace share of $758B pot. Defaults: startup%=0.5, functioning=0.4.
A6: Key | B6: Commodity | C6: Budget USD/yr | D6: Budget $B/yr | E6: Current Mt/yr | F6: CAPEX sheet | G6: Ramp-up sheet
A7: nh3 | B7: NH3 (Ammonia / N) | C7: 5.0751703e+11 | D7: 507.51703 | E7: 240 | F7: NH3 CAPEX | G7: NH3 Ramp-up
A8: phosphate | B8: Phosphate Fertilizer (P / TSP / MAP+DAP) | C8: 6.2132239e+10 | D8: 62.132239 | E8: 47.8 | F8: P CAPEX | G8: P Ramp-up
A9: potassium | B9: Potassium Fertilizer (K / Potash / MOP) | C9: 4.1622939e+10 | D9: 41.622939 | E9: 41.6 | F9: K CAPEX | G9: K Ramp-up
A10: herbicide | B10: Herbicides | C10: 9.3119641e+10 | D10: 93.119641 | E10: 1.9902 | F10: Herb CAPEX | G10: Herb Ramp-up
A11: fungicide | B11: Fungicides & bactericides | C11: 4.1548522e+10 | D11: 41.548522 | E11: 0.8624 | F11: Fun CAPEX | G11: Fun Ramp-up
A12: insecticide | B12: Insecticides | C12: 8.5555493e+09 | D12: 8.5555493 | E12: 0.8232 | F12: Ins CAPEX | G12: Ins Ramp-up
A13: h2so4 | B13: Sulfuric Acid (H2SO4) | C13: 3.5040845e+09 | D13: 3.5040845 | E13: 150 | F13: H2SO4 CAPEX | G13: H2SO4 Ramp-up
A15: Open any '* Ramp-up' tab for parameters, wave table, weekly series, and charts.

Sheet NH3 CAPEX
A1: NH3 CAPEX Calcs
A2: EuroChem Kingisepp benchmark (updated)
D5: Target Plant Size (tonneNH3/day) | F5: =B16
F11: Fast construction cost factor | H11: 1.47
A12: Reference Plant Capacity (tonnes/day) | B12: 2890 | F12: Fast construction speed factor | H12: 0.32
A13: Reference Plant CAPEX (USD) | B13: 1000000000 | C13: (2015)
A14: USD inflation conversion | B14: 1.33 | C14: (2025) | F14: Fast construction (24/7) CAPEX | H14: =H11*B19
A15: Source | B15: https://www.process-worldwide.com/eurochem-opens-one-billion-dollar-ammonia-plant-in-kingisepp-a-836843/
A16: Target Plant Size (tonneNH3/day) | B16: 3000
A17: Plant scale factor | B17: 1.04 | C17: (sheet shows 1.04; ≈B16/B12)
A18: Cost-Capacity Exponent | B18: 0.7
A19: Target Plant CAPEX (USD) | B19: 1.3686302e+09 | D19: <-- Using this estimate
A20: Check: B13*B14*(B16/B12)^B18 | B20: =B13*B14*(B16/B12)^B18
A21: Capital efficiency | B21: =B19/B16/365 | C21: $/tpa installed

Sheet NH3 Ramp-up
C1: NH3 REGULAR CONSTRUCTION | I1: NH3 FAST CONSTRUCTION | R1: fraction_functioning_after_disruption | U1: CODE-MATCHED (current model)
A2: Annual World Construction Budget | C2: 5.0751703e+11 | I2: 5.0751703e+11 | P2: Sanity check: | Q2: the AEA’s datasets track 490 production plants in development, comprising a total of 438.1 million tons of low-emission and transitional ammonia capacity | U2: C16/I16 = 0.4; startup% = 0.5; budget = equal-pace default
A3: Total Capital Investment Per Plant | C3: ='NH3 CAPEX'!B19 | I3: ='NH3 CAPEX'!H14 | P3: =P4*1000000/('NH3 CAPEX'!B16*365.25) | Q3: plants needed to make 240million metric tonnes per year assuming an average of 2000 metric tonnes/day plant capacity | U3: Multiple = (new Mt/yr + surviving Mt/yr) / current Mt/yr
A4: Number of Plants Per Year | C4: =(C2/C3)*C16 | I4: =(I2/I3)*I16 | P4: 240 | Q4: Current NH3 production in million metric tonnes | U4: Surviving Mt/yr in C22/I22
U5: Multiple chart uses U50:W (1.0 before t=0, then drops to 0.4)
A6: Corrected CAPEX for construction time method | G6: =C3*(1-9.1%-6.6%) | M6: =I3*(1-9.1%-6.6%) | U6: Production chart (G/M) = NEW factory Mt/yr only (starts at 0)
A7: Weeks to Build at Facility Costs | C7: =10.774*LN(0.8*G6)-121.45 | I7: =C7*'NH3 CAPEX'!H12
A8: Waves Per Year | C8: =52/C7 | I8: =52/I7
A9: Plants Per Wave | C9: =(C4/C8) | I9: =(I4/I8)
A10: Plants Per Year | C10: =C9*C8 | I10: =I9*I8
A11: Plants Per Week | C11: =C10/52 | I11: =I10/52
A13: Single Facility Scaled Production (tonnes/week) | C13: ='NH3 CAPEX'!$F5*7 | I13: ='NH3 CAPEX'!$F5*7
A14: Startup % of Fully Scaled Production (break in period) | C14: 0.5 | I14: 0.5
A15: Single Facility Startup Production (tonnes/week) | C15: =C13*C14 | I15: =I13*I14
A16: fraction_functioning_after_disruption (surviving existing + new build share) | C16: 0.4 | I16: 0.4
A17: Time to construct a wave (years) | C17: =C7/52 | I17: =I7/52
A18: Startup time (weeks) | C18: =C7/4 | I18: =I7/4
A19: Startup time (years) | C19: =C18/52 | I19: =I18/52
A20: Planning time (weeks) | C20: 4 | I20: 4
A21: Planning time (years) | C21: =C20/52 | I21: =I20/52
A22: Surviving Mt/yr (= fraction_functioning * current Mt/yr) | C22: =C16*$P$4 | I22: =I16*$P$4
A23: Wave | B23: Production Level | C23: Plants | D23: tonnes/week | E23: Weeks | F23: Years | G23: Megatonnes/year | H23: Multiple of Current NH3 Production | I23: Plants | J23: tonnes/week | K23: Weeks | L23: Years | M23: Megatonnes/year | N23: Multiple of Current NH3 Production | S23: Required | T23: Current | U23: New
A24: 1 | B24: startup production | C24: =C$9*$A24 | D24: =C15*C24 | E24: =F24*52 | F24: =C$17*$A24+C$21 | G24: =D24/1000000*52 | H24: =G24/$P$4+($C$22/$P$4) | I24: =I$9*$A24 | J24: =I15*I24 | K24: =L24*52 | L24: =I$17*$A24+I$21 | M24: =J24/1000000*52 | N24: =M24/$P$4+($I$22/$P$4) | R24: N | S24: 1000 | T24: 1000 | U24: 0
A25: 1 | B25: full production | C25: =C$9*$A25 | D25: =C25*C$13 | E25: =F25*52 | F25: =F24+C$19 | G25: =D25/1000000*52 | H25: =G25/$P$4+($C$22/$P$4) | I25: =I$9*$A25 | J25: =I25*I$13 | K25: =L25*52 | L25: =L24+I$19 | M25: =J25/1000000*52 | N25: =M25/$P$4+($I$22/$P$4) | R25: 0.7 | T25: 700
A26: 2 | B26: startup production | C26: =C$9*$A26 | D26: =D25+C$15*C$9 | E26: =F26*52 | F26: =C$17*$A26+C$21 | G26: =D26/1000000*52 | H26: =G26/$P$4+($C$22/$P$4) | I26: =I$9*$A26 | J26: =J25+I$15*I$9 | K26: =L26*52 | L26: =I$17*$A26+I$21 | M26: =J26/1000000*52 | N26: =M26/$P$4+($I$22/$P$4)
A27: 2 | B27: full production | C27: =C$9*$A27 | D27: =C27*C$13 | E27: =F27*52 | F27: =F26+C$19 | G27: =D27/1000000*52 | H27: =G27/$P$4+($C$22/$P$4) | I27: =I$9*$A27 | J27: =I27*I$13 | K27: =L27*52 | L27: =L26+I$19 | M27: =J27/1000000*52 | N27: =M27/$P$4+($I$22/$P$4)
A28: 3 | B28: startup production | C28: =C$9*$A28 | D28: =D27+C$15*C$9 | E28: =F28*52 | F28: =C$17*$A28+C$21 | G28: =D28/1000000*52 | H28: =G28/$P$4+($C$22/$P$4) | I28: =I$9*$A28 | J28: =J27+I$15*I$9 | K28: =L28*52 | L28: =I$17*$A28+I$21 | M28: =J28/1000000*52 | N28: =M28/$P$4+($I$22/$P$4)
A29: 3 | B29: full production | C29: =C$9*$A29 | D29: =C29*C$13 | E29: =F29*52 | F29: =F28+C$19 | G29: =D29/1000000*52 | H29: =G29/$P$4+($C$22/$P$4) | I29: =I$9*$A29 | J29: =I29*I$13 | K29: =L29*52 | L29: =L28+I$19 | M29: =J29/1000000*52 | N29: =M29/$P$4+($I$22/$P$4)
A30: 4 | B30: startup production | C30: =C$9*$A30 | D30: =D29+C$15*C$9 | E30: =F30*52 | F30: =C$17*$A30+C$21 | G30: =D30/1000000*52 | H30: =G30/$P$4+($C$22/$P$4) | I30: =I$9*$A30 | J30: =J29+I$15*I$9 | K30: =L30*52 | L30: =I$17*$A30+I$21 | M30: =J30/1000000*52 | N30: =M30/$P$4+($I$22/$P$4)
A31: 4 | B31: full production | C31: =C$9*$A31 | D31: =C31*C$13 | E31: =F31*52 | F31: =F30+C$19 | G31: =D31/1000000*52 | H31: =G31/$P$4+($C$22/$P$4) | I31: =I$9*$A31 | J31: =I31*I$13 | K31: =L31*52 | L31: =L30+I$19 | M31: =J31/1000000*52 | N31: =M31/$P$4+($I$22/$P$4)
A32: 5 | B32: startup production | C32: =C$9*$A32 | D32: =D31+C$15*C$9 | E32: =F32*52 | F32: =C$17*$A32+C$21 | G32: =D32/1000000*52 | H32: =G32/$P$4+($C$22/$P$4) | I32: =I$9*$A32 | J32: =J31+I$15*I$9 | K32: =L32*52 | L32: =I$17*$A32+I$21 | M32: =J32/1000000*52 | N32: =M32/$P$4+($I$22/$P$4)
A33: 5 | B33: full production | C33: =C$9*$A33 | D33: =C33*C$13 | E33: =F33*52 | F33: =F32+C$19 | G33: =D33/1000000*52 | H33: =G33/$P$4+($C$22/$P$4) | I33: =I$9*$A33 | J33: =I33*I$13 | K33: =L33*52 | L33: =L32+I$19 | M33: =J33/1000000*52 | N33: =M33/$P$4+($I$22/$P$4)
A34: 6 | B34: startup production | C34: =C$9*$A34 | D34: =D33+C$15*C$9 | E34: =F34*52 | F34: =C$17*$A34+C$21 | G34: =D34/1000000*52 | H34: =G34/$P$4+($C$22/$P$4) | I34: =I$9*$A34 | J34: =J33+I$15*I$9 | K34: =L34*52 | L34: =I$17*$A34+I$21 | M34: =J34/1000000*52 | N34: =M34/$P$4+($I$22/$P$4)
A35: 6 | B35: full production | C35: =C$9*$A35 | D35: =C35*C$13 | E35: =F35*52 | F35: =F34+C$19 | G35: =D35/1000000*52 | H35: =G35/$P$4+($C$22/$P$4) | I35: =I$9*$A35 | J35: =I35*I$13 | K35: =L35*52 | L35: =L34+I$19 | M35: =J35/1000000*52 | N35: =M35/$P$4+($I$22/$P$4)
A36: 7 | B36: startup production | C36: =C$9*$A36 | D36: =D35+C$15*C$9 | E36: =F36*52 | F36: =C$17*$A36+C$21 | G36: =D36/1000000*52 | H36: =G36/$P$4+($C$22/$P$4) | I36: =I$9*$A36 | J36: =J35+I$15*I$9 | K36: =L36*52 | L36: =I$17*$A36+I$21 | M36: =J36/1000000*52 | N36: =M36/$P$4+($I$22/$P$4)
A37: 7 | B37: full production | C37: =C$9*$A37 | D37: =C37*C$13 | E37: =F37*52 | F37: =F36+C$19 | G37: =D37/1000000*52 | H37: =G37/$P$4+($C$22/$P$4) | I37: =I$9*$A37 | J37: =I37*I$13 | K37: =L37*52 | L37: =L36+I$19 | M37: =J37/1000000*52 | N37: =M37/$P$4+($I$22/$P$4)
A38: 8 | B38: startup production | C38: =C$9*$A38 | D38: =D37+C$15*C$9 | E38: =F38*52 | F38: =C$17*$A38+C$21 | G38: =D38/1000000*52 | H38: =G38/$P$4+($C$22/$P$4) | I38: =I$9*$A38 | J38: =J37+I$15*I$9 | K38: =L38*52 | L38: =I$17*$A38+I$21 | M38: =J38/1000000*52 | N38: =M38/$P$4+($I$22/$P$4)
A39: 8 | B39: full production | C39: =C$9*$A39 | D39: =C39*C$13 | E39: =F39*52 | F39: =F38+C$19 | G39: =D39/1000000*52 | H39: =G39/$P$4+($C$22/$P$4) | I39: =I$9*$A39 | J39: =I39*I$13 | K39: =L39*52 | L39: =L38+I$19 | M39: =J39/1000000*52 | N39: =M39/$P$4+($I$22/$P$4)
A40: 9 | B40: startup production | C40: =C$9*$A40 | D40: =D39+C$15*C$9 | E40: =F40*52 | F40: =C$17*$A40+C$21 | G40: =D40/1000000*52 | H40: =G40/$P$4+($C$22/$P$4) | I40: =I$9*$A40 | J40: =J39+I$15*I$9 | K40: =L40*52 | L40: =I$17*$A40+I$21 | M40: =J40/1000000*52 | N40: =M40/$P$4+($I$22/$P$4)
A41: 9 | B41: full production | C41: =C$9*$A41 | D41: =C41*C$13 | E41: =F41*52 | F41: =F40+C$19 | G41: =D41/1000000*52 | H41: =G41/$P$4+($C$22/$P$4) | I41: =I$9*$A41 | J41: =I41*I$13 | K41: =L41*52 | L41: =L40+I$19 | M41: =J41/1000000*52 | N41: =M41/$P$4+($I$22/$P$4)
...

Sheet P CAPEX
A1: P (MAP+DAP) CAPEX Calcs
A2: UNIDO TSP 1978$ inflated to 2025$
D5: Target Plant Size (tonneP/day) | F5: =B16
F11: Fast construction cost factor | H11: 1.47
A12: Reference capacity (t/day TSP) | B12: 1200 | F12: Fast construction speed factor | H12: 0.32
A13: Reference total investment (1978 USD) | B13: 70000000
A14: Inflation multiplier (1978→2025) | B14: 4.9240951 | F14: Fast construction (24/7) CAPEX | H14: =H11*B19
A15: Reference CAPEX (2025 USD) | B15: =B13*B14
A16: Target Plant Size (tonnes/day) | B16: 1300
A17: Plant scale factor | B17: =B16/B12
A18: Cost-Capacity Exponent | B18: 0.7
A19: Target Plant CAPEX (USD) | B19: =B15*(B16/B12)^B18 | D19: <-- Using this estimate
A21: Capital efficiency | B21: =B19/B16/365 | C21: $/tpa installed

Sheet P Ramp-up
C1: P (MAP+DAP) REGULAR CONSTRUCTION | I1: P (MAP+DAP) FAST CONSTRUCTION | R1: fraction_functioning_after_disruption | U1: CODE-MATCHED (current model)
A2: Annual World Construction Budget | C2: 6.2132239e+10 | I2: 6.2132239e+10 | P2: Sanity check: | Q2: the AEA’s datasets track 490 production plants in development, comprising a total of 438.1 million tons of low-emission and transitional ammonia capacity | U2: C16/I16 = 0.4; startup% = 0.5; budget = equal-pace default
A3: Total Capital Investment Per Plant | C3: ='P CAPEX'!B19 | I3: ='P CAPEX'!H14 | P3: =P4*1000000/('P CAPEX'!B16*365.25) | Q3: plants needed to make 240million metric tonnes per year assuming an average of 2000 metric tonnes/day plant capacity | U3: Multiple = (new Mt/yr + surviving Mt/yr) / current Mt/yr
A4: Number of Plants Per Year | C4: =(C2/C3)*C16 | I4: =(I2/I3)*I16 | P4: 47.8 | Q4: Current P production in million metric tonnes | U4: Surviving Mt/yr in C22/I22
U5: Multiple chart uses U50:W (1.0 before t=0, then drops to 0.4)
A6: Corrected CAPEX for construction time method | G6: =C3*(1-9.1%-6.6%) | M6: =I3*(1-9.1%-6.6%) | U6: Production chart (G/M) = NEW factory Mt/yr only (starts at 0)
A7: Weeks to Build at Facility Costs | C7: =10.774*LN(0.8*G6)-121.45 | I7: =C7*'P CAPEX'!H12
A8: Waves Per Year | C8: =52/C7 | I8: =52/I7
A9: Plants Per Wave | C9: =(C4/C8) | I9: =(I4/I8)
A10: Plants Per Year | C10: =C9*C8 | I10: =I9*I8
A11: Plants Per Week | C11: =C10/52 | I11: =I10/52
A13: Single Facility Scaled Production (tonnes/week) | C13: ='P CAPEX'!$F5*7 | I13: ='P CAPEX'!$F5*7
A14: Startup % of Fully Scaled Production (break in period) | C14: 0.5 | I14: 0.5
A15: Single Facility Startup Production (tonnes/week) | C15: =C13*C14 | I15: =I13*I14
A16: fraction_functioning_after_disruption (surviving existing + new build share) | C16: 0.4 | I16: 0.4
A17: Time to construct a wave (years) | C17: =C7/52 | I17: =I7/52
A18: Startup time (weeks) | C18: =C7/4 | I18: =I7/4
A19: Startup time (years) | C19: =C18/52 | I19: =I18/52
A20: Planning time (weeks) | C20: 4 | I20: 4
A21: Planning time (years) | C21: =C20/52 | I21: =I20/52
A22: Surviving Mt/yr (= fraction_functioning * current Mt/yr) | C22: =C16*$P$4 | I22: =I16*$P$4
A23: Wave | B23: Production Level | C23: Plants | D23: tonnes/week | E23: Weeks | F23: Years | G23: Megatonnes/year | H23: Multiple of Current P Production | I23: Plants | J23: tonnes/week | K23: Weeks | L23: Years | M23: Megatonnes/year | N23: Multiple of Current P Production | S23: Required | T23: Current | U23: New
A24: 1 | B24: startup production | C24: =C$9*$A24 | D24: =C15*C24 | E24: =F24*52 | F24: =C$17*$A24+C$21 | G24: =D24/1000000*52 | H24: =G24/$P$4+($C$22/$P$4) | I24: =I$9*$A24 | J24: =I15*I24 | K24: =L24*52 | L24: =I$17*$A24+I$21 | M24: =J24/1000000*52 | N24: =M24/$P$4+($I$22/$P$4) | R24: N | S24: 1000 | T24: 1000 | U24: 0
A25: 1 | B25: full production | C25: =C$9*$A25 | D25: =C25*C$13 | E25: =F25*52 | F25: =F24+C$19 | G25: =D25/1000000*52 | H25: =G25/$P$4+($C$22/$P$4) | I25: =I$9*$A25 | J25: =I25*I$13 | K25: =L25*52 | L25: =L24+I$19 | M25: =J25/1000000*52 | N25: =M25/$P$4+($I$22/$P$4) | R25: 0.7 | T25: 700
A26: 2 | B26: startup production | C26: =C$9*$A26 | D26: =D25+C$15*C$9 | E26: =F26*52 | F26: =C$17*$A26+C$21 | G26: =D26/1000000*52 | H26: =G26/$P$4+($C$22/$P$4) | I26: =I$9*$A26 | J26: =J25+I$15*I$9 | K26: =L26*52 | L26: =I$17*$A26+I$21 | M26: =J26/1000000*52 | N26: =M26/$P$4+($I$22/$P$4)
A27: 2 | B27: full production | C27: =C$9*$A27 | D27: =C27*C$13 | E27: =F27*52 | F27: =F26+C$19 | G27: =D27/1000000*52 | H27: =G27/$P$4+($C$22/$P$4) | I27: =I$9*$A27 | J27: =I27*I$13 | K27: =L27*52 | L27: =L26+I$19 | M27: =J27/1000000*52 | N27: =M27/$P$4+($I$22/$P$4)
A28: 3 | B28: startup production | C28: =C$9*$A28 | D28: =D27+C$15*C$9 | E28: =F28*52 | F28: =C$17*$A28+C$21 | G28: =D28/1000000*52 | H28: =G28/$P$4+($C$22/$P$4) | I28: =I$9*$A28 | J28: =J27+I$15*I$9 | K28: =L28*52 | L28: =I$17*$A28+I$21 | M28: =J28/1000000*52 | N28: =M28/$P$4+($I$22/$P$4)
A29: 3 | B29: full production | C29: =C$9*$A29 | D29: =C29*C$13 | E29: =F29*52 | F29: =F28+C$19 | G29: =D29/1000000*52 | H29: =G29/$P$4+($C$22/$P$4) | I29: =I$9*$A29 | J29: =I29*I$13 | K29: =L29*52 | L29: =L28+I$19 | M29: =J29/1000000*52 | N29: =M29/$P$4+($I$22/$P$4)
A30: 4 | B30: startup production | C30: =C$9*$A30 | D30: =D29+C$15*C$9 | E30: =F30*52 | F30: =C$17*$A30+C$21 | G30: =D30/1000000*52 | H30: =G30/$P$4+($C$22/$P$4) | I30: =I$9*$A30 | J30: =J29+I$15*I$9 | K30: =L30*52 | L30: =I$17*$A30+I$21 | M30: =J30/1000000*52 | N30: =M30/$P$4+($I$22/$P$4)
A31: 4 | B31: full production | C31: =C$9*$A31 | D31: =C31*C$13 | E31: =F31*52 | F31: =F30+C$19 | G31: =D31/1000000*52 | H31: =G31/$P$4+($C$22/$P$4) | I31: =I$9*$A31 | J31: =I31*I$13 | K31: =L31*52 | L31: =L30+I$19 | M31: =J31/1000000*52 | N31: =M31/$P$4+($I$22/$P$4)
A32: 5 | B32: startup production | C32: =C$9*$A32 | D32: =D31+C$15*C$9 | E32: =F32*52 | F32: =C$17*$A32+C$21 | G32: =D32/1000000*52 | H32: =G32/$P$4+($C$22/$P$4) | I32: =I$9*$A32 | J32: =J31+I$15*I$9 | K32: =L32*52 | L32: =I$17*$A32+I$21 | M32: =J32/1000000*52 | N32: =M32/$P$4+($I$22/$P$4)
A33: 5 | B33: full production | C33: =C$9*$A33 | D33: =C33*C$13 | E33: =F33*52 | F33: =F32+C$19 | G33: =D33/1000000*52 | H33: =G33/$P$4+($C$22/$P$4) | I33: =I$9*$A33 | J33: =I33*I$13 | K33: =L33*52 | L33: =L32+I$19 | M33: =J33/1000000*52 | N33: =M33/$P$4+($I$22/$P$4)
A34: 6 | B34: startup production | C34: =C$9*$A34 | D34: =D33+C$15*C$9 | E34: =F34*52 | F34: =C$17*$A34+C$21 | G34: =D34/1000000*52 | H34: =G34/$P$4+($C$22/$P$4) | I34: =I$9*$A34 | J34: =J33+I$15*I$9 | K34: =L34*52 | L34: =I$17*$A34+I$21 | M34: =J34/1000000*52 | N34: =M34/$P$4+($I$22/$P$4)
A35: 6 | B35: full production | C35: =C$9*$A35 | D35: =C35*C$13 | E35: =F35*52 | F35: =F34+C$19 | G35: =D35/1000000*52 | H35: =G35/$P$4+($C$22/$P$4) | I35: =I$9*$A35 | J35: =I35*I$13 | K35: =L35*52 | L35: =L34+I$19 | M35: =J35/1000000*52 | N35: =M35/$P$4+($I$22/$P$4)
A36: 7 | B36: startup production | C36: =C$9*$A36 | D36: =D35+C$15*C$9 | E36: =F36*52 | F36: =C$17*$A36+C$21 | G36: =D36/1000000*52 | H36: =G36/$P$4+($C$22/$P$4) | I36: =I$9*$A36 | J36: =J35+I$15*I$9 | K36: =L36*52 | L36: =I$17*$A36+I$21 | M36: =J36/1000000*52 | N36: =M36/$P$4+($I$22/$P$4)
A37: 7 | B37: full production | C37: =C$9*$A37 | D37: =C37*C$13 | E37: =F37*52 | F37: =F36+C$19 | G37: =D37/1000000*52 | H37: =G37/$P$4+($C$22/$P$4) | I37: =I$9*$A37 | J37: =I37*I$13 | K37: =L37*52 | L37: =L36+I$19 | M37: =J37/1000000*52 | N37: =M37/$P$4+($I$22/$P$4)
A38: 8 | B38: startup production | C38: =C$9*$A38 | D38: =D37+C$15*C$9 | E38: =F38*52 | F38: =C$17*$A38+C$21 | G38: =D38/1000000*52 | H38: =G38/$P$4+($C$22/$P$4) | I38: =I$9*$A38 | J38: =J37+I$15*I$9 | K38: =L38*52 | L38: =I$17*$A38+I$21 | M38: =J38/1000000*52 | N38: =M38/$P$4+($I$22/$P$4)
A39: 8 | B39: full production | C39: =C$9*$A39 | D39: =C39*C$13 | E39: =F39*52 | F39: =F38+C$19 | G39: =D39/1000000*52 | H39: =G39/$P$4+($C$22/$P$4) | I39: =I$9*$A39 | J39: =I39*I$13 | K39: =L39*52 | L39: =L38+I$19 | M39: =J39/1000000*52 | N39: =M39/$P$4+($I$22/$P$4)
A40: 9 | B40: startup production | C40: =C$9*$A40 | D40: =D39+C$15*C$9 | E40: =F40*52 | F40: =C$17*$A40+C$21 | G40: =D40/1000000*52 | H40: =G40/$P$4+($C$22/$P$4) | I40: =I$9*$A40 | J40: =J39+I$15*I$9 | K40: =L40*52 | L40: =I$17*$A40+I$21 | M40: =J40/1000000*52 | N40: =M40/$P$4+($I$22/$P$4)
A41: 9 | B41: full production | C41: =C$9*$A41 | D41: =C41*C$13 | E41: =F41*52 | F41: =F40+C$19 | G41: =D41/1000000*52 | H41: =G41/$P$4+($C$22/$P$4) | I41: =I$9*$A41 | J41: =I41*I$13 | K41: =L41*52 | L41: =L40+I$19 | M41: =J41/1000000*52 | N41: =M41/$P$4+($I$22/$P$4)
...

Sheet K CAPEX
A1: K (Potash) CAPEX Calcs
A2: Banio MOP PEA benchmark
D5: Target Plant Size (tonneK/day) | F5: =B16
F11: Fast construction cost factor | H11: 1.47
A12: Reference capacity (t/yr MOP) | B12: 800000 | F12: Fast construction speed factor | H12: 0.32
A13: Reference CAPEX (USD) | B13: 480000000
A14: Target capacity (t/yr) | B14: =B16*365 | F14: Fast construction (24/7) CAPEX | H14: =H11*B19
A15: Plant scale factor | B15: =B14/B12
A16: Target Plant Size (tonnes/day) | B16: 2300
A17: Cost-Capacity Exponent | B17: 0.7
A19: Target Plant CAPEX (USD) | B19: =B13*(B14/B12)^B17 | D19: <-- Using this estimate
A21: Capital efficiency | B21: =B19/B16/365 | C21: $/tpa installed

Sheet K Ramp-up
C1: K (POTASH) REGULAR CONSTRUCTION | I1: K (POTASH) FAST CONSTRUCTION | R1: fraction_functioning_after_disruption | U1: CODE-MATCHED (current model)
A2: Annual World Construction Budget | C2: 4.1622939e+10 | I2: 4.1622939e+10 | P2: Sanity check: | Q2: the AEA’s datasets track 490 production plants in development, comprising a total of 438.1 million tons of low-emission and transitional ammonia capacity | U2: C16/I16 = 0.4; startup% = 0.5; budget = equal-pace default
A3: Total Capital Investment Per Plant | C3: ='K CAPEX'!B19 | I3: ='K CAPEX'!H14 | P3: =P4*1000000/('K CAPEX'!B16*365.25) | Q3: plants needed to make 240million metric tonnes per year assuming an average of 2000 metric tonnes/day plant capacity | U3: Multiple = (new Mt/yr + surviving Mt/yr) / current Mt/yr
A4: Number of Plants Per Year | C4: =(C2/C3)*C16 | I4: =(I2/I3)*I16 | P4: 41.6 | Q4: Current K production in million metric tonnes | U4: Surviving Mt/yr in C22/I22
U5: Multiple chart uses U50:W (1.0 before t=0, then drops to 0.4)
A6: Corrected CAPEX for construction time method | G6: =C3*(1-9.1%-6.6%) | M6: =I3*(1-9.1%-6.6%) | U6: Production chart (G/M) = NEW factory Mt/yr only (starts at 0)
A7: Weeks to Build at Facility Costs | C7: =10.774*LN(0.8*G6)-121.45 | I7: =C7*'K CAPEX'!H12
A8: Waves Per Year | C8: =52/C7 | I8: =52/I7
A9: Plants Per Wave | C9: =(C4/C8) | I9: =(I4/I8)
A10: Plants Per Year | C10: =C9*C8 | I10: =I9*I8
A11: Plants Per Week | C11: =C10/52 | I11: =I10/52
A13: Single Facility Scaled Production (tonnes/week) | C13: ='K CAPEX'!$F5*7 | I13: ='K CAPEX'!$F5*7
A14: Startup % of Fully Scaled Production (break in period) | C14: 0.5 | I14: 0.5
A15: Single Facility Startup Production (tonnes/week) | C15: =C13*C14 | I15: =I13*I14
A16: fraction_functioning_after_disruption (surviving existing + new build share) | C16: 0.4 | I16: 0.4
A17: Time to construct a wave (years) | C17: =C7/52 | I17: =I7/52
A18: Startup time (weeks) | C18: =C7/4 | I18: =I7/4
A19: Startup time (years) | C19: =C18/52 | I19: =I18/52
A20: Planning time (weeks) | C20: 4 | I20: 4
A21: Planning time (years) | C21: =C20/52 | I21: =I20/52
A22: Surviving Mt/yr (= fraction_functioning * current Mt/yr) | C22: =C16*$P$4 | I22: =I16*$P$4
A23: Wave | B23: Production Level | C23: Plants | D23: tonnes/week | E23: Weeks | F23: Years | G23: Megatonnes/year | H23: Multiple of Current K Production | I23: Plants | J23: tonnes/week | K23: Weeks | L23: Years | M23: Megatonnes/year | N23: Multiple of Current K Production | S23: Required | T23: Current | U23: New
A24: 1 | B24: startup production | C24: =C$9*$A24 | D24: =C15*C24 | E24: =F24*52 | F24: =C$17*$A24+C$21 | G24: =D24/1000000*52 | H24: =G24/$P$4+($C$22/$P$4) | I24: =I$9*$A24 | J24: =I15*I24 | K24: =L24*52 | L24: =I$17*$A24+I$21 | M24: =J24/1000000*52 | N24: =M24/$P$4+($I$22/$P$4) | R24: N | S24: 1000 | T24: 1000 | U24: 0
A25: 1 | B25: full production | C25: =C$9*$A25 | D25: =C25*C$13 | E25: =F25*52 | F25: =F24+C$19 | G25: =D25/1000000*52 | H25: =G25/$P$4+($C$22/$P$4) | I25: =I$9*$A25 | J25: =I25*I$13 | K25: =L25*52 | L25: =L24+I$19 | M25: =J25/1000000*52 | N25: =M25/$P$4+($I$22/$P$4) | R25: 0.7 | T25: 700
A26: 2 | B26: startup production | C26: =C$9*$A26 | D26: =D25+C$15*C$9 | E26: =F26*52 | F26: =C$17*$A26+C$21 | G26: =D26/1000000*52 | H26: =G26/$P$4+($C$22/$P$4) | I26: =I$9*$A26 | J26: =J25+I$15*I$9 | K26: =L26*52 | L26: =I$17*$A26+I$21 | M26: =J26/1000000*52 | N26: =M26/$P$4+($I$22/$P$4)
A27: 2 | B27: full production | C27: =C$9*$A27 | D27: =C27*C$13 | E27: =F27*52 | F27: =F26+C$19 | G27: =D27/1000000*52 | H27: =G27/$P$4+($C$22/$P$4) | I27: =I$9*$A27 | J27: =I27*I$13 | K27: =L27*52 | L27: =L26+I$19 | M27: =J27/1000000*52 | N27: =M27/$P$4+($I$22/$P$4)
A28: 3 | B28: startup production | C28: =C$9*$A28 | D28: =D27+C$15*C$9 | E28: =F28*52 | F28: =C$17*$A28+C$21 | G28: =D28/1000000*52 | H28: =G28/$P$4+($C$22/$P$4) | I28: =I$9*$A28 | J28: =J27+I$15*I$9 | K28: =L28*52 | L28: =I$17*$A28+I$21 | M28: =J28/1000000*52 | N28: =M28/$P$4+($I$22/$P$4)
A29: 3 | B29: full production | C29: =C$9*$A29 | D29: =C29*C$13 | E29: =F29*52 | F29: =F28+C$19 | G29: =D29/1000000*52 | H29: =G29/$P$4+($C$22/$P$4) | I29: =I$9*$A29 | J29: =I29*I$13 | K29: =L29*52 | L29: =L28+I$19 | M29: =J29/1000000*52 | N29: =M29/$P$4+($I$22/$P$4)
A30: 4 | B30: startup production | C30: =C$9*$A30 | D30: =D29+C$15*C$9 | E30: =F30*52 | F30: =C$17*$A30+C$21 | G30: =D30/1000000*52 | H30: =G30/$P$4+($C$22/$P$4) | I30: =I$9*$A30 | J30: =J29+I$15*I$9 | K30: =L30*52 | L30: =I$17*$A30+I$21 | M30: =J30/1000000*52 | N30: =M30/$P$4+($I$22/$P$4)
A31: 4 | B31: full production | C31: =C$9*$A31 | D31: =C31*C$13 | E31: =F31*52 | F31: =F30+C$19 | G31: =D31/1000000*52 | H31: =G31/$P$4+($C$22/$P$4) | I31: =I$9*$A31 | J31: =I31*I$13 | K31: =L31*52 | L31: =L30+I$19 | M31: =J31/1000000*52 | N31: =M31/$P$4+($I$22/$P$4)
A32: 5 | B32: startup production | C32: =C$9*$A32 | D32: =D31+C$15*C$9 | E32: =F32*52 | F32: =C$17*$A32+C$21 | G32: =D32/1000000*52 | H32: =G32/$P$4+($C$22/$P$4) | I32: =I$9*$A32 | J32: =J31+I$15*I$9 | K32: =L32*52 | L32: =I$17*$A32+I$21 | M32: =J32/1000000*52 | N32: =M32/$P$4+($I$22/$P$4)
A33: 5 | B33: full production | C33: =C$9*$A33 | D33: =C33*C$13 | E33: =F33*52 | F33: =F32+C$19 | G33: =D33/1000000*52 | H33: =G33/$P$4+($C$22/$P$4) | I33: =I$9*$A33 | J33: =I33*I$13 | K33: =L33*52 | L33: =L32+I$19 | M33: =J33/1000000*52 | N33: =M33/$P$4+($I$22/$P$4)
A34: 6 | B34: startup production | C34: =C$9*$A34 | D34: =D33+C$15*C$9 | E34: =F34*52 | F34: =C$17*$A34+C$21 | G34: =D34/1000000*52 | H34: =G34/$P$4+($C$22/$P$4) | I34: =I$9*$A34 | J34: =J33+I$15*I$9 | K34: =L34*52 | L34: =I$17*$A34+I$21 | M34: =J34/1000000*52 | N34: =M34/$P$4+($I$22/$P$4)
A35: 6 | B35: full production | C35: =C$9*$A35 | D35: =C35*C$13 | E35: =F35*52 | F35: =F34+C$19 | G35: =D35/1000000*52 | H35: =G35/$P$4+($C$22/$P$4) | I35: =I$9*$A35 | J35: =I35*I$13 | K35: =L35*52 | L35: =L34+I$19 | M35: =J35/1000000*52 | N35: =M35/$P$4+($I$22/$P$4)
A36: 7 | B36: startup production | C36: =C$9*$A36 | D36: =D35+C$15*C$9 | E36: =F36*52 | F36: =C$17*$A36+C$21 | G36: =D36/1000000*52 | H36: =G36/$P$4+($C$22/$P$4) | I36: =I$9*$A36 | J36: =J35+I$15*I$9 | K36: =L36*52 | L36: =I$17*$A36+I$21 | M36: =J36/1000000*52 | N36: =M36/$P$4+($I$22/$P$4)
A37: 7 | B37: full production | C37: =C$9*$A37 | D37: =C37*C$13 | E37: =F37*52 | F37: =F36+C$19 | G37: =D37/1000000*52 | H37: =G37/$P$4+($C$22/$P$4) | I37: =I$9*$A37 | J37: =I37*I$13 | K37: =L37*52 | L37: =L36+I$19 | M37: =J37/1000000*52 | N37: =M37/$P$4+($I$22/$P$4)
A38: 8 | B38: startup production | C38: =C$9*$A38 | D38: =D37+C$15*C$9 | E38: =F38*52 | F38: =C$17*$A38+C$21 | G38: =D38/1000000*52 | H38: =G38/$P$4+($C$22/$P$4) | I38: =I$9*$A38 | J38: =J37+I$15*I$9 | K38: =L38*52 | L38: =I$17*$A38+I$21 | M38: =J38/1000000*52 | N38: =M38/$P$4+($I$22/$P$4)
A39: 8 | B39: full production | C39: =C$9*$A39 | D39: =C39*C$13 | E39: =F39*52 | F39: =F38+C$19 | G39: =D39/1000000*52 | H39: =G39/$P$4+($C$22/$P$4) | I39: =I$9*$A39 | J39: =I39*I$13 | K39: =L39*52 | L39: =L38+I$19 | M39: =J39/1000000*52 | N39: =M39/$P$4+($I$22/$P$4)
A40: 9 | B40: startup production | C40: =C$9*$A40 | D40: =D39+C$15*C$9 | E40: =F40*52 | F40: =C$17*$A40+C$21 | G40: =D40/1000000*52 | H40: =G40/$P$4+($C$22/$P$4) | I40: =I$9*$A40 | J40: =J39+I$15*I$9 | K40: =L40*52 | L40: =I$17*$A40+I$21 | M40: =J40/1000000*52 | N40: =M40/$P$4+($I$22/$P$4)
A41: 9 | B41: full production | C41: =C$9*$A41 | D41: =C41*C$13 | E41: =F41*52 | F41: =F40+C$19 | G41: =D41/1000000*52 | H41: =G41/$P$4+($C$22/$P$4) | I41: =I$9*$A41 | J41: =I41*I$13 | K41: =L41*52 | L41: =L40+I$19 | M41: =J41/1000000*52 | N41: =M41/$P$4+($I$22/$P$4)
...

Sheet Herb CAPEX
A1: Herbicide CAPEX Calcs
A2: Pesticide scale-up assumptions 2026
D5: Target Plant Size (tonneHerbicide/day) | F5: =B16
F11: Fast construction cost factor | H11: 1.47
A12: Reference capacity (t/yr) | B12: 500 | F12: Fast construction speed factor | H12: 0.32
A13: Reference CAPEX (USD) | B13: 14605000
A14: Target plant size (t/yr) | B14: 600 | F14: Fast construction (24/7) CAPEX | H14: =H11*B19
A15: Plant scale factor | B15: =B14/B12
A16: Target Plant Size (tonnes/day) [= t/yr / 365] | B16: =B14/365
A17: Cost-Capacity Exponent | B17: 0.7
A18: (for reference)
A19: Target Plant CAPEX (USD) | B19: =B13*(B14/B12)^B17 | D19: <-- Using this estimate
A21: Capital efficiency | B21: =B19/B16/365 | C21: $/tpa installed

Sheet Herb Ramp-up
C1: HERBICIDE REGULAR CONSTRUCTION | I1: HERBICIDE FAST CONSTRUCTION | R1: fraction_functioning_after_disruption | U1: CODE-MATCHED (current model)
A2: Annual World Construction Budget | C2: 9.3119641e+10 | I2: 9.3119641e+10 | P2: Sanity check: | Q2: the AEA’s datasets track 490 production plants in development, comprising a total of 438.1 million tons of low-emission and transitional ammonia capacity | U2: C16/I16 = 0.4; startup% = 0.5; budget = equal-pace default
A3: Total Capital Investment Per Plant | C3: ='Herb CAPEX'!B19 | I3: ='Herb CAPEX'!H14 | P3: =P4*1000000/('Herb CAPEX'!B16*365.25) | Q3: plants needed to make 240million metric tonnes per year assuming an average of 2000 metric tonnes/day plant capacity | U3: Multiple = (new Mt/yr + surviving Mt/yr) / current Mt/yr
A4: Number of Plants Per Year | C4: =(C2/C3)*C16 | I4: =(I2/I3)*I16 | P4: 1.9902 | Q4: Current Herbicide production in million metric tonnes | U4: Surviving Mt/yr in C22/I22
U5: Multiple chart uses U50:W (1.0 before t=0, then drops to 0.4)
A6: Corrected CAPEX for construction time method | G6: =C3*(1-9.1%-6.6%) | M6: =I3*(1-9.1%-6.6%) | U6: Production chart (G/M) = NEW factory Mt/yr only (starts at 0)
A7: Weeks to Build at Facility Costs | C7: =10.774*LN(0.8*G6)-121.45 | I7: =C7*'Herb CAPEX'!H12
A8: Waves Per Year | C8: =52/C7 | I8: =52/I7
A9: Plants Per Wave | C9: =(C4/C8) | I9: =(I4/I8)
A10: Plants Per Year | C10: =C9*C8 | I10: =I9*I8
A11: Plants Per Week | C11: =C10/52 | I11: =I10/52
A13: Single Facility Scaled Production (tonnes/week) | C13: ='Herb CAPEX'!$F5*7 | I13: ='Herb CAPEX'!$F5*7
A14: Startup % of Fully Scaled Production (break in period) | C14: 0.5 | I14: 0.5
A15: Single Facility Startup Production (tonnes/week) | C15: =C13*C14 | I15: =I13*I14
A16: fraction_functioning_after_disruption (surviving existing + new build share) | C16: 0.4 | I16: 0.4
A17: Time to construct a wave (years) | C17: =C7/52 | I17: =I7/52
A18: Startup time (weeks) | C18: =C7/4 | I18: =I7/4
A19: Startup time (years) | C19: =C18/52 | I19: =I18/52
A20: Planning time (weeks) | C20: 4 | I20: 4
A21: Planning time (years) | C21: =C20/52 | I21: =I20/52
A22: Surviving Mt/yr (= fraction_functioning * current Mt/yr) | C22: =C16*$P$4 | I22: =I16*$P$4
A23: Wave | B23: Production Level | C23: Plants | D23: tonnes/week | E23: Weeks | F23: Years | G23: Megatonnes/year | H23: Multiple of Current Herbicide Production | I23: Plants | J23: tonnes/week | K23: Weeks | L23: Years | M23: Megatonnes/year | N23: Multiple of Current Herbicide Production | S23: Required | T23: Current | U23: New
A24: 1 | B24: startup production | C24: =C$9*$A24 | D24: =C15*C24 | E24: =F24*52 | F24: =C$17*$A24+C$21 | G24: =D24/1000000*52 | H24: =G24/$P$4+($C$22/$P$4) | I24: =I$9*$A24 | J24: =I15*I24 | K24: =L24*52 | L24: =I$17*$A24+I$21 | M24: =J24/1000000*52 | N24: =M24/$P$4+($I$22/$P$4) | R24: N | S24: 1000 | T24: 1000 | U24: 0
A25: 1 | B25: full production | C25: =C$9*$A25 | D25: =C25*C$13 | E25: =F25*52 | F25: =F24+C$19 | G25: =D25/1000000*52 | H25: =G25/$P$4+($C$22/$P$4) | I25: =I$9*$A25 | J25: =I25*I$13 | K25: =L25*52 | L25: =L24+I$19 | M25: =J25/1000000*52 | N25: =M25/$P$4+($I$22/$P$4) | R25: 0.7 | T25: 700
A26: 2 | B26: startup production | C26: =C$9*$A26 | D26: =D25+C$15*C$9 | E26: =F26*52 | F26: =C$17*$A26+C$21 | G26: =D26/1000000*52 | H26: =G26/$P$4+($C$22/$P$4) | I26: =I$9*$A26 | J26: =J25+I$15*I$9 | K26: =L26*52 | L26: =I$17*$A26+I$21 | M26: =J26/1000000*52 | N26: =M26/$P$4+($I$22/$P$4)
A27: 2 | B27: full production | C27: =C$9*$A27 | D27: =C27*C$13 | E27: =F27*52 | F27: =F26+C$19 | G27: =D27/1000000*52 | H27: =G27/$P$4+($C$22/$P$4) | I27: =I$9*$A27 | J27: =I27*I$13 | K27: =L27*52 | L27: =L26+I$19 | M27: =J27/1000000*52 | N27: =M27/$P$4+($I$22/$P$4)
A28: 3 | B28: startup production | C28: =C$9*$A28 | D28: =D27+C$15*C$9 | E28: =F28*52 | F28: =C$17*$A28+C$21 | G28: =D28/1000000*52 | H28: =G28/$P$4+($C$22/$P$4) | I28: =I$9*$A28 | J28: =J27+I$15*I$9 | K28: =L28*52 | L28: =I$17*$A28+I$21 | M28: =J28/1000000*52 | N28: =M28/$P$4+($I$22/$P$4)
A29: 3 | B29: full production | C29: =C$9*$A29 | D29: =C29*C$13 | E29: =F29*52 | F29: =F28+C$19 | G29: =D29/1000000*52 | H29: =G29/$P$4+($C$22/$P$4) | I29: =I$9*$A29 | J29: =I29*I$13 | K29: =L29*52 | L29: =L28+I$19 | M29: =J29/1000000*52 | N29: =M29/$P$4+($I$22/$P$4)
A30: 4 | B30: startup production | C30: =C$9*$A30 | D30: =D29+C$15*C$9 | E30: =F30*52 | F30: =C$17*$A30+C$21 | G30: =D30/1000000*52 | H30: =G30/$P$4+($C$22/$P$4) | I30: =I$9*$A30 | J30: =J29+I$15*I$9 | K30: =L30*52 | L30: =I$17*$A30+I$21 | M30: =J30/1000000*52 | N30: =M30/$P$4+($I$22/$P$4)
A31: 4 | B31: full production | C31: =C$9*$A31 | D31: =C31*C$13 | E31: =F31*52 | F31: =F30+C$19 | G31: =D31/1000000*52 | H31: =G31/$P$4+($C$22/$P$4) | I31: =I$9*$A31 | J31: =I31*I$13 | K31: =L31*52 | L31: =L30+I$19 | M31: =J31/1000000*52 | N31: =M31/$P$4+($I$22/$P$4)
A32: 5 | B32: startup production | C32: =C$9*$A32 | D32: =D31+C$15*C$9 | E32: =F32*52 | F32: =C$17*$A32+C$21 | G32: =D32/1000000*52 | H32: =G32/$P$4+($C$22/$P$4) | I32: =I$9*$A32 | J32: =J31+I$15*I$9 | K32: =L32*52 | L32: =I$17*$A32+I$21 | M32: =J32/1000000*52 | N32: =M32/$P$4+($I$22/$P$4)
A33: 5 | B33: full production | C33: =C$9*$A33 | D33: =C33*C$13 | E33: =F33*52 | F33: =F32+C$19 | G33: =D33/1000000*52 | H33: =G33/$P$4+($C$22/$P$4) | I33: =I$9*$A33 | J33: =I33*I$13 | K33: =L33*52 | L33: =L32+I$19 | M33: =J33/1000000*52 | N33: =M33/$P$4+($I$22/$P$4)
A34: 6 | B34: startup production | C34: =C$9*$A34 | D34: =D33+C$15*C$9 | E34: =F34*52 | F34: =C$17*$A34+C$21 | G34: =D34/1000000*52 | H34: =G34/$P$4+($C$22/$P$4) | I34: =I$9*$A34 | J34: =J33+I$15*I$9 | K34: =L34*52 | L34: =I$17*$A34+I$21 | M34: =J34/1000000*52 | N34: =M34/$P$4+($I$22/$P$4)
A35: 6 | B35: full production | C35: =C$9*$A35 | D35: =C35*C$13 | E35: =F35*52 | F35: =F34+C$19 | G35: =D35/1000000*52 | H35: =G35/$P$4+($C$22/$P$4) | I35: =I$9*$A35 | J35: =I35*I$13 | K35: =L35*52 | L35: =L34+I$19 | M35: =J35/1000000*52 | N35: =M35/$P$4+($I$22/$P$4)
A36: 7 | B36: startup production | C36: =C$9*$A36 | D36: =D35+C$15*C$9 | E36: =F36*52 | F36: =C$17*$A36+C$21 | G36: =D36/1000000*52 | H36: =G36/$P$4+($C$22/$P$4) | I36: =I$9*$A36 | J36: =J35+I$15*I$9 | K36: =L36*52 | L36: =I$17*$A36+I$21 | M36: =J36/1000000*52 | N36: =M36/$P$4+($I$22/$P$4)
A37: 7 | B37: full production | C37: =C$9*$A37 | D37: =C37*C$13 | E37: =F37*52 | F37: =F36+C$19 | G37: =D37/1000000*52 | H37: =G37/$P$4+($C$22/$P$4) | I37: =I$9*$A37 | J37: =I37*I$13 | K37: =L37*52 | L37: =L36+I$19 | M37: =J37/1000000*52 | N37: =M37/$P$4+($I$22/$P$4)
A38: 8 | B38: startup production | C38: =C$9*$A38 | D38: =D37+C$15*C$9 | E38: =F38*52 | F38: =C$17*$A38+C$21 | G38: =D38/1000000*52 | H38: =G38/$P$4+($C$22/$P$4) | I38: =I$9*$A38 | J38: =J37+I$15*I$9 | K38: =L38*52 | L38: =I$17*$A38+I$21 | M38: =J38/1000000*52 | N38: =M38/$P$4+($I$22/$P$4)
A39: 8 | B39: full production | C39: =C$9*$A39 | D39: =C39*C$13 | E39: =F39*52 | F39: =F38+C$19 | G39: =D39/1000000*52 | H39: =G39/$P$4+($C$22/$P$4) | I39: =I$9*$A39 | J39: =I39*I$13 | K39: =L39*52 | L39: =L38+I$19 | M39: =J39/1000000*52 | N39: =M39/$P$4+($I$22/$P$4)
A40: 9 | B40: startup production | C40: =C$9*$A40 | D40: =D39+C$15*C$9 | E40: =F40*52 | F40: =C$17*$A40+C$21 | G40: =D40/1000000*52 | H40: =G40/$P$4+($C$22/$P$4) | I40: =I$9*$A40 | J40: =J39+I$15*I$9 | K40: =L40*52 | L40: =I$17*$A40+I$21 | M40: =J40/1000000*52 | N40: =M40/$P$4+($I$22/$P$4)
A41: 9 | B41: full production | C41: =C$9*$A41 | D41: =C41*C$13 | E41: =F41*52 | F41: =F40+C$19 | G41: =D41/1000000*52 | H41: =G41/$P$4+($C$22/$P$4) | I41: =I$9*$A41 | J41: =I41*I$13 | K41: =L41*52 | L41: =L40+I$19 | M41: =J41/1000000*52 | N41: =M41/$P$4+($I$22/$P$4)
...

Sheet Fun CAPEX
A1: Fungicide CAPEX Calcs
A2: Pesticide scale-up assumptions 2026
D5: Target Plant Size (tonneFungicide/day) | F5: =B16
F11: Fast construction cost factor | H11: 1.47
A12: Reference capacity (t/yr) | B12: 1000 | F12: Fast construction speed factor | H12: 0.32
A13: Reference CAPEX (USD) | B13: 29302000
A14: Target plant size (t/yr) | B14: 1100 | F14: Fast construction (24/7) CAPEX | H14: =H11*B19
A15: Plant scale factor | B15: =B14/B12
A16: Target Plant Size (tonnes/day) [= t/yr / 365] | B16: =B14/365
A17: Cost-Capacity Exponent | B17: 0.7
A18: (for reference)
A19: Target Plant CAPEX (USD) | B19: =B13*(B14/B12)^B17 | D19: <-- Using this estimate
A21: Capital efficiency | B21: =B19/B16/365 | C21: $/tpa installed

Sheet Fun Ramp-up
C1: FUNGICIDE REGULAR CONSTRUCTION | I1: FUNGICIDE FAST CONSTRUCTION | R1: fraction_functioning_after_disruption | U1: CODE-MATCHED (current model)
A2: Annual World Construction Budget | C2: 4.1548522e+10 | I2: 4.1548522e+10 | P2: Sanity check: | Q2: the AEA’s datasets track 490 production plants in development, comprising a total of 438.1 million tons of low-emission and transitional ammonia capacity | U2: C16/I16 = 0.4; startup% = 0.5; budget = equal-pace default
A3: Total Capital Investment Per Plant | C3: ='Fun CAPEX'!B19 | I3: ='Fun CAPEX'!H14 | P3: =P4*1000000/('Fun CAPEX'!B16*365.25) | Q3: plants needed to make 240million metric tonnes per year assuming an average of 2000 metric tonnes/day plant capacity | U3: Multiple = (new Mt/yr + surviving Mt/yr) / current Mt/yr
A4: Number of Plants Per Year | C4: =(C2/C3)*C16 | I4: =(I2/I3)*I16 | P4: 0.8624 | Q4: Current Fungicide production in million metric tonnes | U4: Surviving Mt/yr in C22/I22
U5: Multiple chart uses U50:W (1.0 before t=0, then drops to 0.4)
A6: Corrected CAPEX for construction time method | G6: =C3*(1-9.1%-6.6%) | M6: =I3*(1-9.1%-6.6%) | U6: Production chart (G/M) = NEW factory Mt/yr only (starts at 0)
A7: Weeks to Build at Facility Costs | C7: =10.774*LN(0.8*G6)-121.45 | I7: =C7*'Fun CAPEX'!H12
A8: Waves Per Year | C8: =52/C7 | I8: =52/I7
A9: Plants Per Wave | C9: =(C4/C8) | I9: =(I4/I8)
A10: Plants Per Year | C10: =C9*C8 | I10: =I9*I8
A11: Plants Per Week | C11: =C10/52 | I11: =I10/52
A13: Single Facility Scaled Production (tonnes/week) | C13: ='Fun CAPEX'!$F5*7 | I13: ='Fun CAPEX'!$F5*7
A14: Startup % of Fully Scaled Production (break in period) | C14: 0.5 | I14: 0.5
A15: Single Facility Startup Production (tonnes/week) | C15: =C13*C14 | I15: =I13*I14
A16: fraction_functioning_after_disruption (surviving existing + new build share) | C16: 0.4 | I16: 0.4
A17: Time to construct a wave (years) | C17: =C7/52 | I17: =I7/52
A18: Startup time (weeks) | C18: =C7/4 | I18: =I7/4
A19: Startup time (years) | C19: =C18/52 | I19: =I18/52
A20: Planning time (weeks) | C20: 4 | I20: 4
A21: Planning time (years) | C21: =C20/52 | I21: =I20/52
A22: Surviving Mt/yr (= fraction_functioning * current Mt/yr) | C22: =C16*$P$4 | I22: =I16*$P$4
A23: Wave | B23: Production Level | C23: Plants | D23: tonnes/week | E23: Weeks | F23: Years | G23: Megatonnes/year | H23: Multiple of Current Fungicide Production | I23: Plants | J23: tonnes/week | K23: Weeks | L23: Years | M23: Megatonnes/year | N23: Multiple of Current Fungicide Production | S23: Required | T23: Current | U23: New
A24: 1 | B24: startup production | C24: =C$9*$A24 | D24: =C15*C24 | E24: =F24*52 | F24: =C$17*$A24+C$21 | G24: =D24/1000000*52 | H24: =G24/$P$4+($C$22/$P$4) | I24: =I$9*$A24 | J24: =I15*I24 | K24: =L24*52 | L24: =I$17*$A24+I$21 | M24: =J24/1000000*52 | N24: =M24/$P$4+($I$22/$P$4) | R24: N | S24: 1000 | T24: 1000 | U24: 0
A25: 1 | B25: full production | C25: =C$9*$A25 | D25: =C25*C$13 | E25: =F25*52 | F25: =F24+C$19 | G25: =D25/1000000*52 | H25: =G25/$P$4+($C$22/$P$4) | I25: =I$9*$A25 | J25: =I25*I$13 | K25: =L25*52 | L25: =L24+I$19 | M25: =J25/1000000*52 | N25: =M25/$P$4+($I$22/$P$4) | R25: 0.7 | T25: 700
A26: 2 | B26: startup production | C26: =C$9*$A26 | D26: =D25+C$15*C$9 | E26: =F26*52 | F26: =C$17*$A26+C$21 | G26: =D26/1000000*52 | H26: =G26/$P$4+($C$22/$P$4) | I26: =I$9*$A26 | J26: =J25+I$15*I$9 | K26: =L26*52 | L26: =I$17*$A26+I$21 | M26: =J26/1000000*52 | N26: =M26/$P$4+($I$22/$P$4)
A27: 2 | B27: full production | C27: =C$9*$A27 | D27: =C27*C$13 | E27: =F27*52 | F27: =F26+C$19 | G27: =D27/1000000*52 | H27: =G27/$P$4+($C$22/$P$4) | I27: =I$9*$A27 | J27: =I27*I$13 | K27: =L27*52 | L27: =L26+I$19 | M27: =J27/1000000*52 | N27: =M27/$P$4+($I$22/$P$4)
A28: 3 | B28: startup production | C28: =C$9*$A28 | D28: =D27+C$15*C$9 | E28: =F28*52 | F28: =C$17*$A28+C$21 | G28: =D28/1000000*52 | H28: =G28/$P$4+($C$22/$P$4) | I28: =I$9*$A28 | J28: =J27+I$15*I$9 | K28: =L28*52 | L28: =I$17*$A28+I$21 | M28: =J28/1000000*52 | N28: =M28/$P$4+($I$22/$P$4)
A29: 3 | B29: full production | C29: =C$9*$A29 | D29: =C29*C$13 | E29: =F29*52 | F29: =F28+C$19 | G29: =D29/1000000*52 | H29: =G29/$P$4+($C$22/$P$4) | I29: =I$9*$A29 | J29: =I29*I$13 | K29: =L29*52 | L29: =L28+I$19 | M29: =J29/1000000*52 | N29: =M29/$P$4+($I$22/$P$4)
A30: 4 | B30: startup production | C30: =C$9*$A30 | D30: =D29+C$15*C$9 | E30: =F30*52 | F30: =C$17*$A30+C$21 | G30: =D30/1000000*52 | H30: =G30/$P$4+($C$22/$P$4) | I30: =I$9*$A30 | J30: =J29+I$15*I$9 | K30: =L30*52 | L30: =I$17*$A30+I$21 | M30: =J30/1000000*52 | N30: =M30/$P$4+($I$22/$P$4)
A31: 4 | B31: full production | C31: =C$9*$A31 | D31: =C31*C$13 | E31: =F31*52 | F31: =F30+C$19 | G31: =D31/1000000*52 | H31: =G31/$P$4+($C$22/$P$4) | I31: =I$9*$A31 | J31: =I31*I$13 | K31: =L31*52 | L31: =L30+I$19 | M31: =J31/1000000*52 | N31: =M31/$P$4+($I$22/$P$4)
A32: 5 | B32: startup production | C32: =C$9*$A32 | D32: =D31+C$15*C$9 | E32: =F32*52 | F32: =C$17*$A32+C$21 | G32: =D32/1000000*52 | H32: =G32/$P$4+($C$22/$P$4) | I32: =I$9*$A32 | J32: =J31+I$15*I$9 | K32: =L32*52 | L32: =I$17*$A32+I$21 | M32: =J32/1000000*52 | N32: =M32/$P$4+($I$22/$P$4)
A33: 5 | B33: full production | C33: =C$9*$A33 | D33: =C33*C$13 | E33: =F33*52 | F33: =F32+C$19 | G33: =D33/1000000*52 | H33: =G33/$P$4+($C$22/$P$4) | I33: =I$9*$A33 | J33: =I33*I$13 | K33: =L33*52 | L33: =L32+I$19 | M33: =J33/1000000*52 | N33: =M33/$P$4+($I$22/$P$4)
A34: 6 | B34: startup production | C34: =C$9*$A34 | D34: =D33+C$15*C$9 | E34: =F34*52 | F34: =C$17*$A34+C$21 | G34: =D34/1000000*52 | H34: =G34/$P$4+($C$22/$P$4) | I34: =I$9*$A34 | J34: =J33+I$15*I$9 | K34: =L34*52 | L34: =I$17*$A34+I$21 | M34: =J34/1000000*52 | N34: =M34/$P$4+($I$22/$P$4)
A35: 6 | B35: full production | C35: =C$9*$A35 | D35: =C35*C$13 | E35: =F35*52 | F35: =F34+C$19 | G35: =D35/1000000*52 | H35: =G35/$P$4+($C$22/$P$4) | I35: =I$9*$A35 | J35: =I35*I$13 | K35: =L35*52 | L35: =L34+I$19 | M35: =J35/1000000*52 | N35: =M35/$P$4+($I$22/$P$4)
A36: 7 | B36: startup production | C36: =C$9*$A36 | D36: =D35+C$15*C$9 | E36: =F36*52 | F36: =C$17*$A36+C$21 | G36: =D36/1000000*52 | H36: =G36/$P$4+($C$22/$P$4) | I36: =I$9*$A36 | J36: =J35+I$15*I$9 | K36: =L36*52 | L36: =I$17*$A36+I$21 | M36: =J36/1000000*52 | N36: =M36/$P$4+($I$22/$P$4)
A37: 7 | B37: full production | C37: =C$9*$A37 | D37: =C37*C$13 | E37: =F37*52 | F37: =F36+C$19 | G37: =D37/1000000*52 | H37: =G37/$P$4+($C$22/$P$4) | I37: =I$9*$A37 | J37: =I37*I$13 | K37: =L37*52 | L37: =L36+I$19 | M37: =J37/1000000*52 | N37: =M37/$P$4+($I$22/$P$4)
A38: 8 | B38: startup production | C38: =C$9*$A38 | D38: =D37+C$15*C$9 | E38: =F38*52 | F38: =C$17*$A38+C$21 | G38: =D38/1000000*52 | H38: =G38/$P$4+($C$22/$P$4) | I38: =I$9*$A38 | J38: =J37+I$15*I$9 | K38: =L38*52 | L38: =I$17*$A38+I$21 | M38: =J38/1000000*52 | N38: =M38/$P$4+($I$22/$P$4)
A39: 8 | B39: full production | C39: =C$9*$A39 | D39: =C39*C$13 | E39: =F39*52 | F39: =F38+C$19 | G39: =D39/1000000*52 | H39: =G39/$P$4+($C$22/$P$4) | I39: =I$9*$A39 | J39: =I39*I$13 | K39: =L39*52 | L39: =L38+I$19 | M39: =J39/1000000*52 | N39: =M39/$P$4+($I$22/$P$4)
A40: 9 | B40: startup production | C40: =C$9*$A40 | D40: =D39+C$15*C$9 | E40: =F40*52 | F40: =C$17*$A40+C$21 | G40: =D40/1000000*52 | H40: =G40/$P$4+($C$22/$P$4) | I40: =I$9*$A40 | J40: =J39+I$15*I$9 | K40: =L40*52 | L40: =I$17*$A40+I$21 | M40: =J40/1000000*52 | N40: =M40/$P$4+($I$22/$P$4)
A41: 9 | B41: full production | C41: =C$9*$A41 | D41: =C41*C$13 | E41: =F41*52 | F41: =F40+C$19 | G41: =D41/1000000*52 | H41: =G41/$P$4+($C$22/$P$4) | I41: =I$9*$A41 | J41: =I41*I$13 | K41: =L41*52 | L41: =L40+I$19 | M41: =J41/1000000*52 | N41: =M41/$P$4+($I$22/$P$4)
...

Sheet Ins CAPEX
A1: Insecticide CAPEX Calcs
A2: Pesticide scale-up assumptions 2026
D5: Target Plant Size (tonneInsecticide/day) | F5: =B16
F11: Fast construction cost factor | H11: 1.47
A12: Reference capacity (t/yr) | B12: 2000 | F12: Fast construction speed factor | H12: 0.32
A13: Reference CAPEX (USD) | B13: 12467000
A14: Target plant size (t/yr) | B14: 2100 | F14: Fast construction (24/7) CAPEX | H14: =H11*B19
A15: Plant scale factor | B15: =B14/B12
A16: Target Plant Size (tonnes/day) [= t/yr / 365] | B16: =B14/365
A17: Cost-Capacity Exponent | B17: 0.7
A18: (for reference)
A19: Target Plant CAPEX (USD) | B19: =B13*(B14/B12)^B17 | D19: <-- Using this estimate
A21: Capital efficiency | B21: =B19/B16/365 | C21: $/tpa installed

Sheet Ins Ramp-up
C1: INSECTICIDE REGULAR CONSTRUCTION | I1: INSECTICIDE FAST CONSTRUCTION | R1: fraction_functioning_after_disruption | U1: CODE-MATCHED (current model)
A2: Annual World Construction Budget | C2: 8.5555493e+09 | I2: 8.5555493e+09 | P2: Sanity check: | Q2: the AEA’s datasets track 490 production plants in development, comprising a total of 438.1 million tons of low-emission and transitional ammonia capacity | U2: C16/I16 = 0.4; startup% = 0.5; budget = equal-pace default
A3: Total Capital Investment Per Plant | C3: ='Ins CAPEX'!B19 | I3: ='Ins CAPEX'!H14 | P3: =P4*1000000/('Ins CAPEX'!B16*365.25) | Q3: plants needed to make 240million metric tonnes per year assuming an average of 2000 metric tonnes/day plant capacity | U3: Multiple = (new Mt/yr + surviving Mt/yr) / current Mt/yr
A4: Number of Plants Per Year | C4: =(C2/C3)*C16 | I4: =(I2/I3)*I16 | P4: 0.8232 | Q4: Current Insecticide production in million metric tonnes | U4: Surviving Mt/yr in C22/I22
U5: Multiple chart uses U50:W (1.0 before t=0, then drops to 0.4)
A6: Corrected CAPEX for construction time method | G6: =C3*(1-9.1%-6.6%) | M6: =I3*(1-9.1%-6.6%) | U6: Production chart (G/M) = NEW factory Mt/yr only (starts at 0)
A7: Weeks to Build at Facility Costs | C7: =10.774*LN(0.8*G6)-121.45 | I7: =C7*'Ins CAPEX'!H12
A8: Waves Per Year | C8: =52/C7 | I8: =52/I7
A9: Plants Per Wave | C9: =(C4/C8) | I9: =(I4/I8)
A10: Plants Per Year | C10: =C9*C8 | I10: =I9*I8
A11: Plants Per Week | C11: =C10/52 | I11: =I10/52
A13: Single Facility Scaled Production (tonnes/week) | C13: ='Ins CAPEX'!$F5*7 | I13: ='Ins CAPEX'!$F5*7
A14: Startup % of Fully Scaled Production (break in period) | C14: 0.5 | I14: 0.5
A15: Single Facility Startup Production (tonnes/week) | C15: =C13*C14 | I15: =I13*I14
A16: fraction_functioning_after_disruption (surviving existing + new build share) | C16: 0.4 | I16: 0.4
A17: Time to construct a wave (years) | C17: =C7/52 | I17: =I7/52
A18: Startup time (weeks) | C18: =C7/4 | I18: =I7/4
A19: Startup time (years) | C19: =C18/52 | I19: =I18/52
A20: Planning time (weeks) | C20: 4 | I20: 4
A21: Planning time (years) | C21: =C20/52 | I21: =I20/52
A22: Surviving Mt/yr (= fraction_functioning * current Mt/yr) | C22: =C16*$P$4 | I22: =I16*$P$4
A23: Wave | B23: Production Level | C23: Plants | D23: tonnes/week | E23: Weeks | F23: Years | G23: Megatonnes/year | H23: Multiple of Current Insecticide Production | I23: Plants | J23: tonnes/week | K23: Weeks | L23: Years | M23: Megatonnes/year | N23: Multiple of Current Insecticide Production | S23: Required | T23: Current | U23: New
A24: 1 | B24: startup production | C24: =C$9*$A24 | D24: =C15*C24 | E24: =F24*52 | F24: =C$17*$A24+C$21 | G24: =D24/1000000*52 | H24: =G24/$P$4+($C$22/$P$4) | I24: =I$9*$A24 | J24: =I15*I24 | K24: =L24*52 | L24: =I$17*$A24+I$21 | M24: =J24/1000000*52 | N24: =M24/$P$4+($I$22/$P$4) | R24: N | S24: 1000 | T24: 1000 | U24: 0
A25: 1 | B25: full production | C25: =C$9*$A25 | D25: =C25*C$13 | E25: =F25*52 | F25: =F24+C$19 | G25: =D25/1000000*52 | H25: =G25/$P$4+($C$22/$P$4) | I25: =I$9*$A25 | J25: =I25*I$13 | K25: =L25*52 | L25: =L24+I$19 | M25: =J25/1000000*52 | N25: =M25/$P$4+($I$22/$P$4) | R25: 0.7 | T25: 700
A26: 2 | B26: startup production | C26: =C$9*$A26 | D26: =D25+C$15*C$9 | E26: =F26*52 | F26: =C$17*$A26+C$21 | G26: =D26/1000000*52 | H26: =G26/$P$4+($C$22/$P$4) | I26: =I$9*$A26 | J26: =J25+I$15*I$9 | K26: =L26*52 | L26: =I$17*$A26+I$21 | M26: =J26/1000000*52 | N26: =M26/$P$4+($I$22/$P$4)
A27: 2 | B27: full production | C27: =C$9*$A27 | D27: =C27*C$13 | E27: =F27*52 | F27: =F26+C$19 | G27: =D27/1000000*52 | H27: =G27/$P$4+($C$22/$P$4) | I27: =I$9*$A27 | J27: =I27*I$13 | K27: =L27*52 | L27: =L26+I$19 | M27: =J27/1000000*52 | N27: =M27/$P$4+($I$22/$P$4)
A28: 3 | B28: startup production | C28: =C$9*$A28 | D28: =D27+C$15*C$9 | E28: =F28*52 | F28: =C$17*$A28+C$21 | G28: =D28/1000000*52 | H28: =G28/$P$4+($C$22/$P$4) | I28: =I$9*$A28 | J28: =J27+I$15*I$9 | K28: =L28*52 | L28: =I$17*$A28+I$21 | M28: =J28/1000000*52 | N28: =M28/$P$4+($I$22/$P$4)
A29: 3 | B29: full production | C29: =C$9*$A29 | D29: =C29*C$13 | E29: =F29*52 | F29: =F28+C$19 | G29: =D29/1000000*52 | H29: =G29/$P$4+($C$22/$P$4) | I29: =I$9*$A29 | J29: =I29*I$13 | K29: =L29*52 | L29: =L28+I$19 | M29: =J29/1000000*52 | N29: =M29/$P$4+($I$22/$P$4)
A30: 4 | B30: startup production | C30: =C$9*$A30 | D30: =D29+C$15*C$9 | E30: =F30*52 | F30: =C$17*$A30+C$21 | G30: =D30/1000000*52 | H30: =G30/$P$4+($C$22/$P$4) | I30: =I$9*$A30 | J30: =J29+I$15*I$9 | K30: =L30*52 | L30: =I$17*$A30+I$21 | M30: =J30/1000000*52 | N30: =M30/$P$4+($I$22/$P$4)
A31: 4 | B31: full production | C31: =C$9*$A31 | D31: =C31*C$13 | E31: =F31*52 | F31: =F30+C$19 | G31: =D31/1000000*52 | H31: =G31/$P$4+($C$22/$P$4) | I31: =I$9*$A31 | J31: =I31*I$13 | K31: =L31*52 | L31: =L30+I$19 | M31: =J31/1000000*52 | N31: =M31/$P$4+($I$22/$P$4)
A32: 5 | B32: startup production | C32: =C$9*$A32 | D32: =D31+C$15*C$9 | E32: =F32*52 | F32: =C$17*$A32+C$21 | G32: =D32/1000000*52 | H32: =G32/$P$4+($C$22/$P$4) | I32: =I$9*$A32 | J32: =J31+I$15*I$9 | K32: =L32*52 | L32: =I$17*$A32+I$21 | M32: =J32/1000000*52 | N32: =M32/$P$4+($I$22/$P$4)
A33: 5 | B33: full production | C33: =C$9*$A33 | D33: =C33*C$13 | E33: =F33*52 | F33: =F32+C$19 | G33: =D33/1000000*52 | H33: =G33/$P$4+($C$22/$P$4) | I33: =I$9*$A33 | J33: =I33*I$13 | K33: =L33*52 | L33: =L32+I$19 | M33: =J33/1000000*52 | N33: =M33/$P$4+($I$22/$P$4)
A34: 6 | B34: startup production | C34: =C$9*$A34 | D34: =D33+C$15*C$9 | E34: =F34*52 | F34: =C$17*$A34+C$21 | G34: =D34/1000000*52 | H34: =G34/$P$4+($C$22/$P$4) | I34: =I$9*$A34 | J34: =J33+I$15*I$9 | K34: =L34*52 | L34: =I$17*$A34+I$21 | M34: =J34/1000000*52 | N34: =M34/$P$4+($I$22/$P$4)
A35: 6 | B35: full production | C35: =C$9*$A35 | D35: =C35*C$13 | E35: =F35*52 | F35: =F34+C$19 | G35: =D35/1000000*52 | H35: =G35/$P$4+($C$22/$P$4) | I35: =I$9*$A35 | J35: =I35*I$13 | K35: =L35*52 | L35: =L34+I$19 | M35: =J35/1000000*52 | N35: =M35/$P$4+($I$22/$P$4)
A36: 7 | B36: startup production | C36: =C$9*$A36 | D36: =D35+C$15*C$9 | E36: =F36*52 | F36: =C$17*$A36+C$21 | G36: =D36/1000000*52 | H36: =G36/$P$4+($C$22/$P$4) | I36: =I$9*$A36 | J36: =J35+I$15*I$9 | K36: =L36*52 | L36: =I$17*$A36+I$21 | M36: =J36/1000000*52 | N36: =M36/$P$4+($I$22/$P$4)
A37: 7 | B37: full production | C37: =C$9*$A37 | D37: =C37*C$13 | E37: =F37*52 | F37: =F36+C$19 | G37: =D37/1000000*52 | H37: =G37/$P$4+($C$22/$P$4) | I37: =I$9*$A37 | J37: =I37*I$13 | K37: =L37*52 | L37: =L36+I$19 | M37: =J37/1000000*52 | N37: =M37/$P$4+($I$22/$P$4)
A38: 8 | B38: startup production | C38: =C$9*$A38 | D38: =D37+C$15*C$9 | E38: =F38*52 | F38: =C$17*$A38+C$21 | G38: =D38/1000000*52 | H38: =G38/$P$4+($C$22/$P$4) | I38: =I$9*$A38 | J38: =J37+I$15*I$9 | K38: =L38*52 | L38: =I$17*$A38+I$21 | M38: =J38/1000000*52 | N38: =M38/$P$4+($I$22/$P$4)
A39: 8 | B39: full production | C39: =C$9*$A39 | D39: =C39*C$13 | E39: =F39*52 | F39: =F38+C$19 | G39: =D39/1000000*52 | H39: =G39/$P$4+($C$22/$P$4) | I39: =I$9*$A39 | J39: =I39*I$13 | K39: =L39*52 | L39: =L38+I$19 | M39: =J39/1000000*52 | N39: =M39/$P$4+($I$22/$P$4)
A40: 9 | B40: startup production | C40: =C$9*$A40 | D40: =D39+C$15*C$9 | E40: =F40*52 | F40: =C$17*$A40+C$21 | G40: =D40/1000000*52 | H40: =G40/$P$4+($C$22/$P$4) | I40: =I$9*$A40 | J40: =J39+I$15*I$9 | K40: =L40*52 | L40: =I$17*$A40+I$21 | M40: =J40/1000000*52 | N40: =M40/$P$4+($I$22/$P$4)
A41: 9 | B41: full production | C41: =C$9*$A41 | D41: =C41*C$13 | E41: =F41*52 | F41: =F40+C$19 | G41: =D41/1000000*52 | H41: =G41/$P$4+($C$22/$P$4) | I41: =I$9*$A41 | J41: =I41*I$13 | K41: =L41*52 | L41: =L40+I$19 | M41: =J41/1000000*52 | N41: =M41/$P$4+($I$22/$P$4)
...

Sheet H2SO4 CAPEX
A1: H2SO4 CAPEX Calcs
A2: UNIDO-based H2SO4 workbook
D5: Target Plant Size (tonneH2SO4/day) | F5: =B16
F11: Fast construction cost factor | H11: 1.47
A12: Reference capacity (t/day) | B12: 30 | F12: Fast construction speed factor | H12: 0.32
A13: Reference CAPEX (USD) | B13: 216967
A14: Cost-Capacity Exponent | B14: 0.7 | F14: Fast construction (24/7) CAPEX | H14: =H11*B19
A15: Plant scale factor | B15: =B16/B12
A16: Target Plant Size (tonnes/day) | B16: 100
A19: Target Plant CAPEX (USD) | B19: =B13*(B16/B12)^B14 | D19: <-- Using this estimate
A21: Capital efficiency | B21: =B19/B16/365 | C21: $/tpa installed

Sheet H2SO4 Ramp-up
C1: H2SO4 REGULAR CONSTRUCTION | I1: H2SO4 FAST CONSTRUCTION | R1: fraction_functioning_after_disruption | U1: CODE-MATCHED (current model)
A2: Annual World Construction Budget | C2: 3.5040845e+09 | I2: 3.5040845e+09 | P2: Sanity check: | Q2: the AEA’s datasets track 490 production plants in development, comprising a total of 438.1 million tons of low-emission and transitional ammonia capacity | U2: C16/I16 = 0.4; startup% = 0.5; budget = equal-pace default
A3: Total Capital Investment Per Plant | C3: ='H2SO4 CAPEX'!B19 | I3: ='H2SO4 CAPEX'!H14 | P3: =P4*1000000/('H2SO4 CAPEX'!B16*365.25) | Q3: plants needed to make 240million metric tonnes per year assuming an average of 2000 metric tonnes/day plant capacity | U3: Multiple = (new Mt/yr + surviving Mt/yr) / current Mt/yr
A4: Number of Plants Per Year | C4: =(C2/C3)*C16 | I4: =(I2/I3)*I16 | P4: 150 | Q4: Current H2SO4 production in million metric tonnes | U4: Surviving Mt/yr in C22/I22
U5: Multiple chart uses U50:W (1.0 before t=0, then drops to 0.4)
A6: Corrected CAPEX for construction time method | G6: =C3*(1-9.1%-6.6%) | M6: =I3*(1-9.1%-6.6%) | U6: Production chart (G/M) = NEW factory Mt/yr only (starts at 0)
A7: Weeks to Build at Facility Costs | C7: =10.774*LN(0.8*G6)-121.45 | I7: =C7*'H2SO4 CAPEX'!H12
A8: Waves Per Year | C8: =52/C7 | I8: =52/I7
A9: Plants Per Wave | C9: =(C4/C8) | I9: =(I4/I8)
A10: Plants Per Year | C10: =C9*C8 | I10: =I9*I8
A11: Plants Per Week | C11: =C10/52 | I11: =I10/52
A13: Single Facility Scaled Production (tonnes/week) | C13: ='H2SO4 CAPEX'!$F5*7 | I13: ='H2SO4 CAPEX'!$F5*7
A14: Startup % of Fully Scaled Production (break in period) | C14: 0.5 | I14: 0.5
A15: Single Facility Startup Production (tonnes/week) | C15: =C13*C14 | I15: =I13*I14
A16: fraction_functioning_after_disruption (surviving existing + new build share) | C16: 0.4 | I16: 0.4
A17: Time to construct a wave (years) | C17: =C7/52 | I17: =I7/52
A18: Startup time (weeks) | C18: =C7/4 | I18: =I7/4
A19: Startup time (years) | C19: =C18/52 | I19: =I18/52
A20: Planning time (weeks) | C20: 4 | I20: 4
A21: Planning time (years) | C21: =C20/52 | I21: =I20/52
A22: Surviving Mt/yr (= fraction_functioning * current Mt/yr) | C22: =C16*$P$4 | I22: =I16*$P$4
A23: Wave | B23: Production Level | C23: Plants | D23: tonnes/week | E23: Weeks | F23: Years | G23: Megatonnes/year | H23: Multiple of Current H2SO4 Production | I23: Plants | J23: tonnes/week | K23: Weeks | L23: Years | M23: Megatonnes/year | N23: Multiple of Current H2SO4 Production | S23: Required | T23: Current | U23: New
A24: 1 | B24: startup production | C24: =C$9*$A24 | D24: =C15*C24 | E24: =F24*52 | F24: =C$17*$A24+C$21 | G24: =D24/1000000*52 | H24: =G24/$P$4+($C$22/$P$4) | I24: =I$9*$A24 | J24: =I15*I24 | K24: =L24*52 | L24: =I$17*$A24+I$21 | M24: =J24/1000000*52 | N24: =M24/$P$4+($I$22/$P$4) | R24: N | S24: 1000 | T24: 1000 | U24: 0
A25: 1 | B25: full production | C25: =C$9*$A25 | D25: =C25*C$13 | E25: =F25*52 | F25: =F24+C$19 | G25: =D25/1000000*52 | H25: =G25/$P$4+($C$22/$P$4) | I25: =I$9*$A25 | J25: =I25*I$13 | K25: =L25*52 | L25: =L24+I$19 | M25: =J25/1000000*52 | N25: =M25/$P$4+($I$22/$P$4) | R25: 0.7 | T25: 700
A26: 2 | B26: startup production | C26: =C$9*$A26 | D26: =D25+C$15*C$9 | E26: =F26*52 | F26: =C$17*$A26+C$21 | G26: =D26/1000000*52 | H26: =G26/$P$4+($C$22/$P$4) | I26: =I$9*$A26 | J26: =J25+I$15*I$9 | K26: =L26*52 | L26: =I$17*$A26+I$21 | M26: =J26/1000000*52 | N26: =M26/$P$4+($I$22/$P$4)
A27: 2 | B27: full production | C27: =C$9*$A27 | D27: =C27*C$13 | E27: =F27*52 | F27: =F26+C$19 | G27: =D27/1000000*52 | H27: =G27/$P$4+($C$22/$P$4) | I27: =I$9*$A27 | J27: =I27*I$13 | K27: =L27*52 | L27: =L26+I$19 | M27: =J27/1000000*52 | N27: =M27/$P$4+($I$22/$P$4)
A28: 3 | B28: startup production | C28: =C$9*$A28 | D28: =D27+C$15*C$9 | E28: =F28*52 | F28: =C$17*$A28+C$21 | G28: =D28/1000000*52 | H28: =G28/$P$4+($C$22/$P$4) | I28: =I$9*$A28 | J28: =J27+I$15*I$9 | K28: =L28*52 | L28: =I$17*$A28+I$21 | M28: =J28/1000000*52 | N28: =M28/$P$4+($I$22/$P$4)
A29: 3 | B29: full production | C29: =C$9*$A29 | D29: =C29*C$13 | E29: =F29*52 | F29: =F28+C$19 | G29: =D29/1000000*52 | H29: =G29/$P$4+($C$22/$P$4) | I29: =I$9*$A29 | J29: =I29*I$13 | K29: =L29*52 | L29: =L28+I$19 | M29: =J29/1000000*52 | N29: =M29/$P$4+($I$22/$P$4)
A30: 4 | B30: startup production | C30: =C$9*$A30 | D30: =D29+C$15*C$9 | E30: =F30*52 | F30: =C$17*$A30+C$21 | G30: =D30/1000000*52 | H30: =G30/$P$4+($C$22/$P$4) | I30: =I$9*$A30 | J30: =J29+I$15*I$9 | K30: =L30*52 | L30: =I$17*$A30+I$21 | M30: =J30/1000000*52 | N30: =M30/$P$4+($I$22/$P$4)
A31: 4 | B31: full production | C31: =C$9*$A31 | D31: =C31*C$13 | E31: =F31*52 | F31: =F30+C$19 | G31: =D31/1000000*52 | H31: =G31/$P$4+($C$22/$P$4) | I31: =I$9*$A31 | J31: =I31*I$13 | K31: =L31*52 | L31: =L30+I$19 | M31: =J31/1000000*52 | N31: =M31/$P$4+($I$22/$P$4)
A32: 5 | B32: startup production | C32: =C$9*$A32 | D32: =D31+C$15*C$9 | E32: =F32*52 | F32: =C$17*$A32+C$21 | G32: =D32/1000000*52 | H32: =G32/$P$4+($C$22/$P$4) | I32: =I$9*$A32 | J32: =J31+I$15*I$9 | K32: =L32*52 | L32: =I$17*$A32+I$21 | M32: =J32/1000000*52 | N32: =M32/$P$4+($I$22/$P$4)
A33: 5 | B33: full production | C33: =C$9*$A33 | D33: =C33*C$13 | E33: =F33*52 | F33: =F32+C$19 | G33: =D33/1000000*52 | H33: =G33/$P$4+($C$22/$P$4) | I33: =I$9*$A33 | J33: =I33*I$13 | K33: =L33*52 | L33: =L32+I$19 | M33: =J33/1000000*52 | N33: =M33/$P$4+($I$22/$P$4)
A34: 6 | B34: startup production | C34: =C$9*$A34 | D34: =D33+C$15*C$9 | E34: =F34*52 | F34: =C$17*$A34+C$21 | G34: =D34/1000000*52 | H34: =G34/$P$4+($C$22/$P$4) | I34: =I$9*$A34 | J34: =J33+I$15*I$9 | K34: =L34*52 | L34: =I$17*$A34+I$21 | M34: =J34/1000000*52 | N34: =M34/$P$4+($I$22/$P$4)
A35: 6 | B35: full production | C35: =C$9*$A35 | D35: =C35*C$13 | E35: =F35*52 | F35: =F34+C$19 | G35: =D35/1000000*52 | H35: =G35/$P$4+($C$22/$P$4) | I35: =I$9*$A35 | J35: =I35*I$13 | K35: =L35*52 | L35: =L34+I$19 | M35: =J35/1000000*52 | N35: =M35/$P$4+($I$22/$P$4)
A36: 7 | B36: startup production | C36: =C$9*$A36 | D36: =D35+C$15*C$9 | E36: =F36*52 | F36: =C$17*$A36+C$21 | G36: =D36/1000000*52 | H36: =G36/$P$4+($C$22/$P$4) | I36: =I$9*$A36 | J36: =J35+I$15*I$9 | K36: =L36*52 | L36: =I$17*$A36+I$21 | M36: =J36/1000000*52 | N36: =M36/$P$4+($I$22/$P$4)
A37: 7 | B37: full production | C37: =C$9*$A37 | D37: =C37*C$13 | E37: =F37*52 | F37: =F36+C$19 | G37: =D37/1000000*52 | H37: =G37/$P$4+($C$22/$P$4) | I37: =I$9*$A37 | J37: =I37*I$13 | K37: =L37*52 | L37: =L36+I$19 | M37: =J37/1000000*52 | N37: =M37/$P$4+($I$22/$P$4)
A38: 8 | B38: startup production | C38: =C$9*$A38 | D38: =D37+C$15*C$9 | E38: =F38*52 | F38: =C$17*$A38+C$21 | G38: =D38/1000000*52 | H38: =G38/$P$4+($C$22/$P$4) | I38: =I$9*$A38 | J38: =J37+I$15*I$9 | K38: =L38*52 | L38: =I$17*$A38+I$21 | M38: =J38/1000000*52 | N38: =M38/$P$4+($I$22/$P$4)
A39: 8 | B39: full production | C39: =C$9*$A39 | D39: =C39*C$13 | E39: =F39*52 | F39: =F38+C$19 | G39: =D39/1000000*52 | H39: =G39/$P$4+($C$22/$P$4) | I39: =I$9*$A39 | J39: =I39*I$13 | K39: =L39*52 | L39: =L38+I$19 | M39: =J39/1000000*52 | N39: =M39/$P$4+($I$22/$P$4)
A40: 9 | B40: startup production | C40: =C$9*$A40 | D40: =D39+C$15*C$9 | E40: =F40*52 | F40: =C$17*$A40+C$21 | G40: =D40/1000000*52 | H40: =G40/$P$4+($C$22/$P$4) | I40: =I$9*$A40 | J40: =J39+I$15*I$9 | K40: =L40*52 | L40: =I$17*$A40+I$21 | M40: =J40/1000000*52 | N40: =M40/$P$4+($I$22/$P$4)
